<?xml version="1.0" ?>
<robot name="12DOFManipulator">
  <joint name="12DOFManipulator__joint1" type="revolute">
    <parent link="12DOFManipulator__world"/>
    <child link="12DOFManipulator__link1"/>
    <origin rpy="0 0 0" xyz="0 0 0"/>
    <axis xyz="0 0 1"/>
    <limit effort="50.0" lower="-1000.0" upper="1000.0" velocity="6.0"/>
  </joint>
  <joint name="12DOFManipulator__joint2" type="revolute">
    <parent link="12DOFManipulator__link1"/>
    <child link="12DOFManipulator__link2"/>
    <origin rpy="0 0 0" xyz="1 0 0"/>
    <axis xyz="0 1 0"/>
    <limit effort="30.0" lower="-1000.0" upper="1000.0" velocity="2.0"/>
  </joint>
  <joint name="12DOFManipulator__joint3" type="revolute">
    <parent link="12DOFManipulator__link2"/>
    <child link="12DOFManipulator__link3"/>
    <origin rpy="0 0 0" xyz="1 0 0"/>
    <axis xyz="0 1 0"/>
    <limit effort="40.0" lower="-1000.0" upper="1000.0" velocity="2.0"/>
  </joint>
  <joint name="12DOFManipulator__joint4" type="revolute">
    <parent link="12DOFManipulator__link3"/>
    <child link="12DOFManipulator__link4"/>
    <origin rpy="0 0 0" xyz="1 0 0"/>
    <axis xyz="0 0 1"/>
    <limit effort="5.0" lower="-1000.0" upper="1000.0" velocity="2.0"/>
  </joint>
  <joint name="12DOFManipulator__joint5" type="revolute">
    <parent link="12DOFManipulator__link4"/>
    <child link="12DOFManipulator__link5"/>
    <origin rpy="0 0 0" xyz="1 0 0"/>
    <axis xyz="0 0 1"/>
    <limit effort="5.0" lower="-1000.0" upper="1000.0" velocity="2.0"/>
  </joint>
  <joint name="12DOFManipulator__joint6" type="revolute">
    <parent link="12DOFManipulator__link5"/>
    <child link="12DOFManipulator__link6"/>
    <origin rpy="0 0 0" xyz="1 0 0"/>
    <axis xyz="0 1 0"/>
    <limit effort="5.0" lower="-1000.0" upper="1000.0" velocity="2.0"/>
  </joint>
  <joint name="12DOFManipulator__joint7" type="revolute">
    <parent link="12DOFManipulator__link6"/>
    <child link="12DOFManipulator__link7"/>
    <origin rpy="0 0 0" xyz="1 0 0"/>
    <axis xyz="0 0 1"/>
    <limit effort="5.0" lower="-1000.0" upper="1000.0" velocity="2.0"/>
  </joint>
  <joint name="12DOFManipulator__joint8" type="revolute">
    <parent link="12DOFManipulator__link7"/>
    <child link="12DOFManipulator__link8"/>
    <origin rpy="0 0 0" xyz="1 0 0"/>
    <axis xyz="0 0 1"/>
    <limit effort="5.0" lower="-1000.0" upper="1000.0" velocity="2.0"/>
  </joint>
  <joint name="12DOFManipulator__joint9" type="revolute">
    <parent link="12DOFManipulator__link8"/>
    <child link="12DOFManipulator__link9"/>
    <origin rpy="0 0 0" xyz="1 0 0"/>
    <axis xyz="0 0 1"/>
    <limit effort="5.0" lower="-1000.0" upper="1000.0" velocity="2.0"/>
  </joint>
  <joint name="12DOFManipulator__joint10" type="revolute">
    <parent link="12DOFManipulator__link9"/>
    <child link="12DOFManipulator__link10"/>
    <origin rpy="0 0 0" xyz="1 0 0"/>
    <axis xyz="0 0 1"/>
    <limit effort="5.0" lower="-1000.0" upper="1000.0" velocity="2.0"/>
  </joint>
  <joint name="12DOFManipulator__joint11" type="revolute">
    <parent link="12DOFManipulator__link10"/>
    <child link="12DOFManipulator__link11"/>
    <origin rpy="0 0 0" xyz="1 0 0"/>
    <axis xyz="0 0 1"/>
    <limit effort="5.0" lower="-1000.0" upper="1000.0" velocity="2.0"/>
  </joint>
  <joint name="12DOFManipulator__joint12" type="revolute">
    <parent link="12DOFManipulator__link11"/>
    <child link="12DOFManipulator__link12"/>
    <origin rpy="0 0 0" xyz="1 0 0"/>
    <axis xyz="0 0 1"/>
    <limit effort="5.0" lower="-1000.0" upper="1000.0" velocity="2.0"/>
  </joint>
  <joint name="12DOFManipulator__joint13" type="fixed">
    <parent link="12DOFManipulator__link12"/>
    <child link="12DOFManipulator__endEffector"/>
    <origin rpy="0 0 0" xyz="1.0625 0     0"/>
    <axis xyz="0 0 0"/>
    <limit effort="0" lower="0" upper="0" velocity="0"/>
  </joint>
  <link name="12DOFManipulator__world">
    <inertial>
      <mass value="0"/>
      <origin rpy="0 0 0" xyz="0 0 0"/>
      <inertia ixx="0" ixy="0" ixz="0" iyy="0" iyz="0" izz="0"/>
    </inertial>
  </link>
  <link name="12DOFManipulator__link1">
    <inertial>
      <mass value="1.0"/>
      <origin rpy="0 0 0" xyz="0.5 0  0"/>
      <inertia ixx="0.005" ixy="0." ixz="0.0" iyy="0.006" iyz="0" izz="0.003"/>
    </inertial>
    <visual name="12DOFManipulator__visual">
      <origin rpy="0 0 0" xyz="0.5 0  0"/>
      <geometry>
        <box size="1 0.15 0.15"/>
      </geometry>
    </visual>
  </link>
  <link name="12DOFManipulator__link2">
    <inertial>
      <mass value="1.0"/>
      <origin rpy="0 0 0" xyz="0.5 0  0"/>
      <inertia ixx="0.005" ixy="0." ixz="0.0" iyy="0.006" iyz="0" izz="0.003"/>
    </inertial>
    <visual name="12DOFManipulator__visual">
      <origin rpy="0 0 0" xyz="0.5 0  0"/>
      <geometry>
        <box size="1 0.15 0.15"/>
      </geometry>
    </visual>
  </link>
  <link name="12DOFManipulator__link3">
    <inertial>
      <mass value="1.0"/>
      <origin rpy="0 0 0" xyz="0.5 0  0"/>
      <inertia ixx="0.005" ixy="0." ixz="0.0" iyy="0.006" iyz="0" izz="0.003"/>
    </inertial>
    <visual name="12DOFManipulator__visual">
      <origin rpy="0 0 0" xyz="0.5 0  0"/>
      <geometry>
        <box size="1 0.15 0.15"/>
      </geometry>
    </visual>
  </link>
  <link name="12DOFManipulator__link4">
    <inertial>
      <mass value="1.0"/>
      <origin rpy="0 0 0" xyz="0.5 0  0"/>
      <inertia ixx="0.005" ixy="0." ixz="0.0" iyy="0.006" iyz="0" izz="0.003"/>
    </inertial>
    <visual name="12DOFManipulator__visual">
      <origin rpy="0 0 0" xyz="0.5 0  0"/>
      <geometry>
        <box size="1 0.15 0.15"/>
      </geometry>
    </visual>
  </link>
  <link name="12DOFManipulator__link5">
    <inertial>
      <mass value="1.0"/>
      <origin rpy="0 0 0" xyz="0.5 0  0"/>
      <inertia ixx="0.005" ixy="0." ixz="0.0" iyy="0.006" iyz="0" izz="0.003"/>
    </inertial>
    <collision name="12DOFManipulator__collision">
      <origin rpy="0 0 0" xyz="0.5 0  0"/>
      <geometry>
        <box size="1 0.15 0.15"/>
      </geometry>
    </collision>
    <visual name="12DOFManipulator__visual">
      <origin rpy="0 0 0" xyz="0.5 0  0"/>
      <geometry>
        <box size="1 0.15 0.15"/>
      </geometry>
    </visual>
  </link>
  <link name="12DOFManipulator__link6">
    <inertial>
      <mass value="1.0"/>
      <origin rpy="0 0 0" xyz="0.5 0  0"/>
      <inertia ixx="0.005" ixy="0." ixz="0.0" iyy="0.006" iyz="0" izz="0.003"/>
    </inertial>
    <collision name="12DOFManipulator__collision">
      <origin rpy="0 0 0" xyz="0.5 0  0"/>
      <geometry>
        <box size="1 0.15 0.15"/>
      </geometry>
    </collision>
    <visual name="12DOFManipulator__visual">
      <origin rpy="0 0 0" xyz="0.5 0  0"/>
      <geometry>
        <box size="1 0.15 0.15"/>
      </geometry>
    </visual>
  </link>
  <link name="12DOFManipulator__link7">
    <inertial>
      <mass value="1.0"/>
      <origin rpy="0 0 0" xyz="0.5 0  0"/>
      <inertia ixx="0.005" ixy="0." ixz="0.0" iyy="0.006" iyz="0" izz="0.003"/>
    </inertial>
    <collision name="12DOFManipulator__collision">
      <origin rpy="0 0 0" xyz="0.5 0  0"/>
      <geometry>
        <box size="1 0.15 0.15"/>
      </geometry>
    </collision>
    <visual name="12DOFManipulator__visual">
      <origin rpy="0 0 0" xyz="0.5 0  0"/>
      <geometry>
        <box size="1 0.15 0.15"/>
      </geometry>
    </visual>
  </link>
  <link name="12DOFManipulator__link8">
    <inertial>
      <mass value="1.0"/>
      <origin rpy="0 0 0" xyz="0.5 0  0"/>
      <inertia ixx="0.005" ixy="0." ixz="0.0" iyy="0.006" iyz="0" izz="0.003"/>
    </inertial>
    <collision name="12DOFManipulator__collision">
      <origin rpy="0 0 0" xyz="0.5 0  0"/>
      <geometry>
        <box size="1 0.15 0.15"/>
      </geometry>
    </collision>
    <visual name="12DOFManipulator__visual">
      <origin rpy="0 0 0" xyz="0.5 0  0"/>
      <geometry>
        <box size="1 0.15 0.15"/>
      </geometry>
    </visual>
  </link>
  <link name="12DOFManipulator__link9">
    <inertial>
      <mass value="1.0"/>
      <origin rpy="0 0 0" xyz="0.5 0  0"/>
      <inertia ixx="0.005" ixy="0." ixz="0.0" iyy="0.006" iyz="0" izz="0.003"/>
    </inertial>
    <collision name="12DOFManipulator__collision">
      <origin rpy="0 0 0" xyz="0.5 0  0"/>
      <geometry>
        <box size="1 0.15 0.15"/>
      </geometry>
    </collision>
    <visual name="12DOFManipulator__visual">
      <origin rpy="0 0 0" xyz="0.5 0  0"/>
      <geometry>
        <box size="1 0.15 0.15"/>
      </geometry>
    </visual>
  </link>
  <link name="12DOFManipulator__link10">
    <inertial>
      <mass value="1.0"/>
      <origin rpy="0 0 0" xyz="0.5 0  0"/>
      <inertia ixx="0.005" ixy="0." ixz="0.0" iyy="0.006" iyz="0" izz="0.003"/>
    </inertial>
    <collision name="12DOFManipulator__collision">
      <origin rpy="0 0 0" xyz="0.5 0  0"/>
      <geometry>
        <box size="1 0.15 0.15"/>
      </geometry>
    </collision>
    <visual name="12DOFManipulator__visual">
      <origin rpy="0 0 0" xyz="0.5 0  0"/>
      <geometry>
        <box size="1 0.15 0.15"/>
      </geometry>
    </visual>
  </link>
  <link name="12DOFManipulator__link11">
    <inertial>
      <mass value="1.0"/>
      <origin rpy="0 0 0" xyz="0.5 0  0"/>
      <inertia ixx="0.005" ixy="0." ixz="0.0" iyy="0.006" iyz="0" izz="0.003"/>
    </inertial>
    <collision name="12DOFManipulator__collision">
      <origin rpy="0 0 0" xyz="0.5 0  0"/>
      <geometry>
        <box size="1 0.15 0.15"/>
      </geometry>
    </collision>
    <visual name="12DOFManipulator__visual">
      <origin rpy="0 0 0" xyz="0.5 0  0"/>
      <geometry>
        <box size="1 0.15 0.15"/>
      </geometry>
    </visual>
  </link>
  <link name="12DOFManipulator__link12">
    <inertial>
      <mass value="1.0"/>
      <origin rpy="0 0 0" xyz="0.5 0  0"/>
      <inertia ixx="0.005" ixy="0." ixz="0.0" iyy="0.006" iyz="0" izz="0.003"/>
    </inertial>
    <collision name="12DOFManipulator__collision">
      <origin rpy="0 0 0" xyz="0.5 0  0"/>
      <geometry>
        <box size="1 0.15 0.15"/>
      </geometry>
    </collision>
    <visual name="12DOFManipulator__visual">
      <origin rpy="0 0 0" xyz="0.5 0  0"/>
      <geometry>
        <box size="1 0.15 0.15"/>
      </geometry>
    </visual>
  </link>
  <link name="12DOFManipulator__endEffector">
    <inertial>
      <mass value="1.0"/>
      <origin rpy="0 0 0" xyz="0 0 0"/>
      <inertia ixx="0.005" ixy="0." ixz="0.0" iyy="0.006" iyz="0" izz="0.003"/>
    </inertial>
    <collision name="12DOFManipulator__endEffector_collision">
      <origin rpy="0 0 0" xyz="0 0 0"/>
      <geometry>
        <box size="0.125 0.1 0.1"/>
      </geometry>
    </collision>
    <visual name="12DOFManipulator__endEffector_visual">
      <origin rpy="0 0 0" xyz="0 0 0"/>
      <geometry>
        <box size="0.125 0.1 0.1"/>
      </geometry>
    </visual>
  </link>
</robot>
