<?xml version="1.0" ?>
<robot name="6DOFManipulator">
  <joint name="6DOFManipulator__joint1" type="revolute">
    <parent link="6DOFManipulator__world"/>
    <child link="6DOFManipulator__link1"/>
    <origin rpy="0 0 0" xyz="0 0 0"/>
    <axis xyz="0 0 1"/>
    <limit effort="50.0" lower="-1000.0" upper="1000.0" velocity="6.0"/>
  </joint>
  <joint name="6DOFManipulator__joint2" type="revolute">
    <parent link="6DOFManipulator__link1"/>
    <child link="6DOFManipulator__link2"/>
    <origin rpy="0 0 0" xyz="1 0 0"/>
    <axis xyz="0 1 0"/>
    <limit effort="30.0" lower="-1000.0" upper="1000.0" velocity="2.0"/>
  </joint>
  <joint name="6DOFManipulator__joint3" type="revolute">
    <parent link="6DOFManipulator__link2"/>
    <child link="6DOFManipulator__link3"/>
    <origin rpy="0 0 0" xyz="1 0 0"/>
    <axis xyz="0 1 0"/>
    <limit effort="40.0" lower="-1000.0" upper="1000.0" velocity="2.0"/>
  </joint>
  <joint name="6DOFManipulator__joint4" type="revolute">
    <parent link="6DOFManipulator__link3"/>
    <child link="6DOFManipulator__link4"/>
    <origin rpy="0 0 0" xyz="1 0 0"/>
    <axis xyz="0 0 1"/>
    <limit effort="5.0" lower="-1000.0" upper="1000.0" velocity="2.0"/>
  </joint>
  <joint name="6DOFManipulator__joint5" type="revolute">
    <parent link="6DOFManipulator__link4"/>
    <child link="6DOFManipulator__link5"/>
    <origin rpy="0 0 0" xyz="1 0 0"/>
    <axis xyz="0 0 1"/>
    <limit effort="5.0" lower="-1000.0" upper="1000.0" velocity="2.0"/>
  </joint>
  <joint name="6DOFManipulator__joint6" type="revolute">
    <parent link="6DOFManipulator__link5"/>
    <child link="6DOFManipulator__link6"/>
    <origin rpy="0 0 0" xyz="1 0 0"/>
    <axis xyz="0 1 0"/>
    <limit effort="5.0" lower="-1000.0" upper="1000.0" velocity="2.0"/>
  </joint>
  <joint name="6DOFManipulator__joint7" type="fixed">
    <parent link="6DOFManipulator__link6"/>
    <child link="6DOFManipulator__endEffector"/>
    <origin rpy="0 0 0" xyz="1.0625 0     0"/>
    <axis xyz="0 0 0"/>
    <limit effort="0" lower="0" upper="0" velocity="0"/>
  </joint>
  <link name="6DOFManipulator__world">
    <inertial>
      <mass value="0"/>
      <origin rpy="0 0 0" xyz="0 0 0"/>
      <inertia ixx="0" ixy="0" ixz="0" iyy="0" iyz="0" izz="0"/>
    </inertial>
  </link>
  <link name="6DOFManipulator__link1">
    <inertial>
      <mass value="1.0"/>
      <origin rpy="0 0 0" xyz="0.5 0  0"/>
      <inertia ixx="0.005" ixy="0." ixz="0.0" iyy="0.006" iyz="0" izz="0.003"/>
    </inertial>
    <visual name="6DOFManipulator__visual">
      <origin rpy="0 0 0" xyz="0.5 0  0"/>
      <geometry>
        <box size="1 0.15 0.15"/>
      </geometry>
    </visual>
  </link>
  <link name="6DOFManipulator__link2">
    <inertial>
      <mass value="1.0"/>
      <origin rpy="0 0 0" xyz="0.5 0  0"/>
      <inertia ixx="0.005" ixy="0." ixz="0.0" iyy="0.006" iyz="0" izz="0.003"/>
    </inertial>
    <visual name="6DOFManipulator__visual">
      <origin rpy="0 0 0" xyz="0.5 0  0"/>
      <geometry>
        <box size="1 0.15 0.15"/>
      </geometry>
    </visual>
  </link>
  <link name="6DOFManipulator__link3">
    <inertial>
      <mass value="1.0"/>
      <origin rpy="0 0 0" xyz="0.5 0  0"/>
      <inertia ixx="0.005" ixy="0." ixz="0.0" iyy="0.006" iyz="0" izz="0.003"/>
    </inertial>
    <visual name="6DOFManipulator__visual">
      <origin rpy="0 0 0" xyz="0.5 0  0"/>
      <geometry>
        <box size="1 0.15 0.15"/>
      </geometry>
    </visual>
  </link>
  <link name="6DOFManipulator__link4">
    <inertial>
      <mass value="1.0"/>
      <origin rpy="0 0 0" xyz="0.5 0  0"/>
      <inertia ixx="0.005" ixy="0." ixz="0.0" iyy="0.006" iyz="0" izz="0.003"/>
    </inertial>
    <visual name="6DOFManipulator__visual">
      <origin rpy="0 0 0" xyz="0.5 0  0"/>
      <geometry>
        <box size="1 0.15 0.15"/>
      </geometry>
    </visual>
  </link>
  <link name="6DOFManipulator__link5">
    <inertial>
      <mass value="1.0"/>
      <origin rpy="0 0 0" xyz="0.5 0  0"/>
      <inertia ixx="0.005" ixy="0." ixz="0.0" iyy="0.006" iyz="0" izz="0.003"/>
    </inertial>
    <collision name="6DOFManipulator__collision">
      <origin rpy="0 0 0" xyz="0.5 0  0"/>
      <geometry>
        <box size="1 0.15 0.15"/>
      </geometry>
    </collision>
    <visual name="6DOFManipulator__visual">
      <origin rpy="0 0 0" xyz="0.5 0  0"/>
      <geometry>
        <box size="1 0.15 0.15"/>
      </geometry>
    </visual>
  </link>
  <link name="6DOFManipulator__link6">
    <inertial>
      <mass value="1.0"/>
      <origin rpy="0 0 0" xyz="0.5 0  0"/>
      <inertia ixx="0.005" ixy="0." ixz="0.0" iyy="0.006" iyz="0" izz="0.003"/>
    </inertial>
    <collision name="6DOFManipulator__collision">
      <origin rpy="0 0 0" xyz="0.5 0  0"/>
      <geometry>
        <box size="1 0.15 0.15"/>
      </geometry>
    </collision>
    <visual name="6DOFManipulator__visual">
      <origin rpy="0 0 0" xyz="0.5 0  0"/>
      <geometry>
        <box size="1 0.15 0.15"/>
      </geometry>
    </visual>
  </link>
  <link name="6DOFManipulator__endEffector">
    <inertial>
      <mass value="1.0"/>
      <origin rpy="0 0 0" xyz="0 0 0"/>
      <inertia ixx="0.005" ixy="0." ixz="0.0" iyy="0.006" iyz="0" izz="0.003"/>
    </inertial>
    <collision name="6DOFManipulator__endEffector_collision">
      <origin rpy="0 0 0" xyz="0 0 0"/>
      <geometry>
        <box size="0.125 0.1 0.1"/>
      </geometry>
    </collision>
    <visual name="6DOFManipulator__endEffector_visual">
      <origin rpy="0 0 0" xyz="0 0 0"/>
      <geometry>
        <box size="0.125 0.1 0.1"/>
      </geometry>
    </visual>
  </link>
</robot>
